[ 2024-04-29 10:23:35,459 ] 96 werkzeug - INFO - [31m[1mWARNING: This is a development server. Do not use it in a production deployment. Use a production WSGI server instead.[0m
 * Running on all addresses (0.0.0.0)
 * Running on http://127.0.0.1:5000
 * Running on http://192.168.1.72:5000
[ 2024-04-29 10:23:35,460 ] 96 werkzeug - INFO - [33mPress CTRL+C to quit[0m
[ 2024-04-29 10:24:23,271 ] 96 werkzeug - INFO - 127.0.0.1 - - [29/Apr/2024 10:24:23] "GET / HTTP/1.1" 200 -
[ 2024-04-29 10:24:23,474 ] 96 werkzeug - INFO - 127.0.0.1 - - [29/Apr/2024 10:24:23] "[33mGET /favicon.ico HTTP/1.1[0m" 404 -
[ 2024-04-29 10:24:41,554 ] 96 werkzeug - INFO - 127.0.0.1 - - [29/Apr/2024 10:24:41] "GET /predictdata HTTP/1.1" 200 -
[ 2024-04-29 10:25:08,611 ] 838 app - ERROR - Exception on /predictdata [POST]
Traceback (most recent call last):
  File "C:\Users\vktaw\Desktop\projects\openai\ML project\src\pipeline\predict_pipeline.py", line 13, in predict
    model_path=os.path.join("artifacts","model.pkl")
NameError: name 'os' is not defined

During handling of the above exception, another exception occurred:

Traceback (most recent call last):
  File "C:\Users\vktaw\Desktop\projects\openai\ML project\env\lib\site-packages\flask\app.py", line 1473, in wsgi_app
    response = self.full_dispatch_request()
  File "C:\Users\vktaw\Desktop\projects\openai\ML project\env\lib\site-packages\flask\app.py", line 882, in full_dispatch_request
    rv = self.handle_user_exception(e)
  File "C:\Users\vktaw\Desktop\projects\openai\ML project\env\lib\site-packages\flask\app.py", line 880, in full_dispatch_request
    rv = self.dispatch_request()
  File "C:\Users\vktaw\Desktop\projects\openai\ML project\env\lib\site-packages\flask\app.py", line 865, in dispatch_request
    return self.ensure_sync(self.view_functions[rule.endpoint])(**view_args)  # type: ignore[no-any-return]
  File "C:\Users\vktaw\Desktop\projects\openai\ML project\app.py", line 39, in predict_datapoint
    results=predict_pipeline.predict(pred_df)
  File "C:\Users\vktaw\Desktop\projects\openai\ML project\src\pipeline\predict_pipeline.py", line 24, in predict
    raise CustomException(e,sys)
src.exception.CustomException: Error occured in python script name [C:\Users\vktaw\Desktop\projects\openai\ML project\src\pipeline\predict_pipeline.py] line number [13] error message[name 'os' is not defined]
[ 2024-04-29 10:25:08,611 ] 96 werkzeug - INFO - 127.0.0.1 - - [29/Apr/2024 10:25:08] "[35m[1mPOST /predictdata HTTP/1.1[0m" 500 -
[ 2024-04-29 10:25:59,064 ] 838 app - ERROR - Exception on /predictdata [POST]
Traceback (most recent call last):
  File "C:\Users\vktaw\Desktop\projects\openai\ML project\src\pipeline\predict_pipeline.py", line 13, in predict
    model_path=os.path.join("artifacts","model.pkl")
NameError: name 'os' is not defined

During handling of the above exception, another exception occurred:

Traceback (most recent call last):
  File "C:\Users\vktaw\Desktop\projects\openai\ML project\env\lib\site-packages\flask\app.py", line 1473, in wsgi_app
    response = self.full_dispatch_request()
  File "C:\Users\vktaw\Desktop\projects\openai\ML project\env\lib\site-packages\flask\app.py", line 882, in full_dispatch_request
    rv = self.handle_user_exception(e)
  File "C:\Users\vktaw\Desktop\projects\openai\ML project\env\lib\site-packages\flask\app.py", line 880, in full_dispatch_request
    rv = self.dispatch_request()
  File "C:\Users\vktaw\Desktop\projects\openai\ML project\env\lib\site-packages\flask\app.py", line 865, in dispatch_request
    return self.ensure_sync(self.view_functions[rule.endpoint])(**view_args)  # type: ignore[no-any-return]
  File "C:\Users\vktaw\Desktop\projects\openai\ML project\app.py", line 39, in predict_datapoint
    results=predict_pipeline.predict(pred_df)
  File "C:\Users\vktaw\Desktop\projects\openai\ML project\src\pipeline\predict_pipeline.py", line 24, in predict
    raise CustomException(e,sys)
src.exception.CustomException: Error occured in python script name [C:\Users\vktaw\Desktop\projects\openai\ML project\src\pipeline\predict_pipeline.py] line number [13] error message[name 'os' is not defined]
[ 2024-04-29 10:25:59,064 ] 96 werkzeug - INFO - 127.0.0.1 - - [29/Apr/2024 10:25:59] "[35m[1mPOST /predictdata HTTP/1.1[0m" 500 -
[ 2024-04-29 10:29:21,688 ] 838 app - ERROR - Exception on /predictdata [POST]
Traceback (most recent call last):
  File "C:\Users\vktaw\Desktop\projects\openai\ML project\src\pipeline\predict_pipeline.py", line 13, in predict
    model_path=os.path.join("artifacts","model.pkl")
NameError: name 'os' is not defined

During handling of the above exception, another exception occurred:

Traceback (most recent call last):
  File "C:\Users\vktaw\Desktop\projects\openai\ML project\env\lib\site-packages\flask\app.py", line 1473, in wsgi_app
    response = self.full_dispatch_request()
  File "C:\Users\vktaw\Desktop\projects\openai\ML project\env\lib\site-packages\flask\app.py", line 882, in full_dispatch_request
    rv = self.handle_user_exception(e)
  File "C:\Users\vktaw\Desktop\projects\openai\ML project\env\lib\site-packages\flask\app.py", line 880, in full_dispatch_request
    rv = self.dispatch_request()
  File "C:\Users\vktaw\Desktop\projects\openai\ML project\env\lib\site-packages\flask\app.py", line 865, in dispatch_request
    return self.ensure_sync(self.view_functions[rule.endpoint])(**view_args)  # type: ignore[no-any-return]
  File "C:\Users\vktaw\Desktop\projects\openai\ML project\app.py", line 39, in predict_datapoint
    results=predict_pipeline.predict(pred_df)
  File "C:\Users\vktaw\Desktop\projects\openai\ML project\src\pipeline\predict_pipeline.py", line 24, in predict
    raise CustomException(e,sys)
src.exception.CustomException: Error occured in python script name [C:\Users\vktaw\Desktop\projects\openai\ML project\src\pipeline\predict_pipeline.py] line number [13] error message[name 'os' is not defined]
[ 2024-04-29 10:29:21,688 ] 96 werkzeug - INFO - 127.0.0.1 - - [29/Apr/2024 10:29:21] "[35m[1mPOST /predictdata HTTP/1.1[0m" 500 -
